From f958bacb9631a7a2e74f11b0ef6f5865b6263920 Mon Sep 17 00:00:00 2001
From: Chris Knorowski <chris.knorowski@sensiml.com>
Date: Wed, 3 Apr 2019 12:06:21 -0700
Subject: [PATCH] Attribute Error should be caught when celery fails to find
 the correct exception

adding simple unit test
---
 celery/backends/base.py      | 2 +-
 t/unit/backends/test_base.py | 9 +++++++++
 2 files changed, 10 insertions(+), 1 deletion(-)

diff --git a/celery/backends/base.py b/celery/backends/base.py
index a51fb04593..e8d94803d2 100644
--- a/celery/backends/base.py
+++ b/celery/backends/base.py
@@ -274,7 +274,7 @@ def exception_to_python(self, exc):
                     exc_type = from_utf8(exc['exc_type'])
                     try:
                         cls = getattr(sys.modules[exc_module], exc_type)
-                    except KeyError:
+                    except (KeyError, AttributeError):
                         cls = create_exception_cls(exc_type,
                                                    celery.exceptions.__name__)
                 exc_msg = exc['exc_message']
